<?xml version="1.0" ?>
<sdf version="1.8">
    <world name="flashbot">
        <!-- Physics - (set to default) -->
        <physics name="1ms" type="ignored">
            <max_step_size>0.001</max_step_size>
            <real_time_factor>1.0</real_time_factor>
        </physics>

        <!-- ================ -->
        <!-- === PLUGINS ==== -->
        <!-- ================= -->
        <plugin filename="libignition-gazebo-physics-system.so" name="ignition::gazebo::systems::Physics">
        </plugin>
        <plugin filename="libignition-gazebo-user-commands-system.so" name="ignition::gazebo::systems::UserCommands">
        </plugin>
        <plugin filename="libignition-gazebo-scene-broadcaster-system.so" name="ignition::gazebo::systems::SceneBroadcaster">
        </plugin>

        <light type="directional" name="sun">
            <cast_shadows>true</cast_shadows>
            <pose>0 0 10 0 0 0</pose>
            <diffuse>0.8 0.8 0.8 1</diffuse>
            <specular>0.2 0.2 0.2 1</specular>
            <attenuation>
                <range>1000</range>
                <constant>0.9</constant>
                <linear>0.01</linear>
                <quadratic>0.001</quadratic>
            </attenuation>
            <direction>-0.5 0.1 -0.9</direction>
        </light>

        <model name="ground_plane">
            <static>true</static>
            <link name="link">
                <collision name="collision">
                    <geometry>
                        <plane>
                            <normal>0 0 1</normal>
                        </plane>
                    </geometry>
                </collision>
                <visual name="visual">
                    <geometry>
                        <plane>
                            <normal>0 0 1</normal>
                            <size>100 100</size>
                        </plane>
                    </geometry>
                    <material>
                        <ambient>0.8 0.8 0.8 1</ambient>
                        <diffuse>0.8 0.8 0.8 1</diffuse>
                        <specular>0.8 0.8 0.8 1</specular>
                    </material>
                </visual>
            </link>
        </model>

        <model name='flashbot' canonical_link='chassis'>
            <!--the pose is relative to the world by default-->
            <pose relative_to='world'>0 0 0 0 0 0</pose>
            <!-- ================== -->
            <!-- ## Main Chassis ## -->
            <!-- ================== -->
            <link name='chassis'>
                <pose relative_to='__model__'>0.5 0 0.4 0 0 0</pose>
                <inertial>                    <!--inertial properties of the link mass, inertia matix-->
                    <mass>1.14395</mass>
                    <inertia>
                        <ixx>0.095329</ixx>
                        <ixy>0</ixy>
                        <ixz>0</ixz>
                        <iyy>0.381317</iyy>
                        <iyz>0</iyz>
                        <izz>0.476646</izz>
                    </inertia>
                </inertial>
                <visual name='visual'>
                    <geometry>
                        <mesh>
                            <uri>model://flashbot/meshes/flashbot.dae</uri>
                        </mesh>
                    </geometry>
                </visual>
                <collision name='collision'>
                    <geometry>
                        <box>
                            <size>2.0 1.0 0.5</size>
                        </box>
                    </geometry>
                </collision>
            </link>

            <!-- ============================================================= -->
            <!-- ######### WHEELS SECTION - (angles are in radians) #########  -->
            <!-- ============================================================= -->

            <!-- ================== -->
            <!-- ## FRONT WHEELS ## -->
            <!-- ================== -->
            <!-- Right front wheel -->
            <link name='right_front_wheel'>
                <pose relative_to="chassis">0.3 -0.15 -0.347 -1.5707 0 0</pose>                
                <inertial>
                    <mass>1</mass>
                    <inertia>
                        <ixx>0.043333</ixx>
                        <ixy>0</ixy>
                        <ixz>0</ixz>
                        <iyy>0.043333</iyy>
                        <iyz>0</iyz>
                        <izz>0.08</izz>
                    </inertia>
                </inertial>
                <visual name='visual'>
                    <geometry>
                        <cylinder>
                            <radius>0.04</radius>
                            <length>0.02</length>
                        </cylinder>
                    </geometry>
                    <material>
                        <ambient>1.0 0.0 0.0 1</ambient>
                        <diffuse>1.0 0.0 0.0 1</diffuse>
                        <specular>1.0 0.0 0.0 1</specular>
                    </material>
                </visual>
                <collision name='collision'>
                    <geometry>
                        <cylinder>
                            <radius>0.4</radius>
                            <length>0.2</length>
                        </cylinder>
                    </geometry>
                </collision>
            </link>
            <!-- Left front wheel -->
            <link name='left_front_wheel'>
                <pose relative_to="chassis">0.3 0.13 -0.347 -1.5707 0 0</pose>
                <inertial>
                    <mass>1</mass>
                    <inertia>
                        <ixx>0.043333</ixx>
                        <ixy>0</ixy>
                        <ixz>0</ixz>
                        <iyy>0.043333</iyy>
                        <iyz>0</iyz>
                        <izz>0.08</izz>
                    </inertia>
                </inertial>
                <visual name='visual'>
                    <geometry>
                        <cylinder>
                            <radius>0.04</radius>
                            <length>0.02</length>
                        </cylinder>
                    </geometry>
                    <material>
                        <ambient>1.0 0.0 0.0 1</ambient>
                        <diffuse>1.0 0.0 0.0 1</diffuse>
                        <specular>1.0 0.0 0.0 1</specular>
                    </material>
                </visual>
                <collision name='collision'>
                    <geometry>
                        <cylinder>
                            <radius>0.4</radius>
                            <length>0.2</length>
                        </cylinder>
                    </geometry>
                </collision>
            </link>

            <!-- ================= -->
            <!-- ## BACK WHEELS ## -->
            <!-- ================= -->
            <!-- Right back wheel -->
            <link name='right_back_wheel'>
                <pose relative_to="chassis">0.1 -0.15 -0.347 -1.5707 0 0</pose>                
                <inertial>
                    <mass>1</mass>
                    <inertia>
                        <ixx>0.043333</ixx>
                        <ixy>0</ixy>
                        <ixz>0</ixz>
                        <iyy>0.043333</iyy>
                        <iyz>0</iyz>
                        <izz>0.08</izz>
                    </inertia>
                </inertial>
                <visual name='visual'>
                    <geometry>
                        <cylinder>
                            <radius>0.04</radius>
                            <length>0.02</length>
                        </cylinder>
                    </geometry>
                    <material>
                        <ambient>1.0 0.0 0.0 1</ambient>
                        <diffuse>1.0 0.0 0.0 1</diffuse>
                        <specular>1.0 0.0 0.0 1</specular>
                    </material>
                </visual>
                <collision name='collision'>
                    <geometry>
                        <cylinder>
                            <radius>0.4</radius>
                            <length>0.2</length>
                        </cylinder>
                    </geometry>
                </collision>
            </link>
            <!-- Left back wheel -->
            <link name='left_back_wheel'>
                <pose relative_to="chassis">0.1 0.13 -0.347 -1.5707 0 0</pose>
                <inertial>
                    <mass>1</mass>
                    <inertia>
                        <ixx>0.043333</ixx>
                        <ixy>0</ixy>
                        <ixz>0</ixz>
                        <iyy>0.043333</iyy>
                        <iyz>0</iyz>
                        <izz>0.08</izz>
                    </inertia>
                </inertial>
                <visual name='visual'>
                    <geometry>
                        <cylinder>
                            <radius>0.04</radius>
                            <length>0.02</length>
                        </cylinder>
                    </geometry>
                    <material>
                        <ambient>1.0 0.0 0.0 1</ambient>
                        <diffuse>1.0 0.0 0.0 1</diffuse>
                        <specular>1.0 0.0 0.0 1</specular>
                    </material>
                </visual>
                <collision name='collision'>
                    <geometry>
                        <cylinder>
                            <radius>0.4</radius>
                            <length>0.2</length>
                        </cylinder>
                    </geometry>
                </collision>
            </link>

            <!-- ============================================================= -->
            <!-- #################### END OF WHEELS #########################  -->
            <!-- ============================================================= -->

            <!-- ================== -->
            <!-- ## CASTER FRAME ## -->
            <!-- ================== -->
            <!--arbitrary frame-->
            <frame name="caster_frame" attached_to='chassis'>
                <pose>0.8 0 -0.2 0 0 0</pose>
            </frame>
            <!--caster wheel-->
            <link name='caster'>
                <pose relative_to='caster_frame'/>
                <inertial>
                    <mass>1</mass>
                    <inertia>
                        <ixx>0.016</ixx>
                        <ixy>0</ixy>
                        <ixz>0</ixz>
                        <iyy>0.016</iyy>
                        <iyz>0</iyz>
                        <izz>0.016</izz>
                    </inertia>
                </inertial>
                <!-- <visual name='visual'>
                    <geometry>
                        <mesh>
                            <uri>model://flashbot/meshes/flashbot.dae</uri>
                        </mesh>
                    </geometry>
                </visual> -->
                <collision name='collision'>
                    <geometry>
                        <sphere>
                            <radius>0.2</radius>
                        </sphere>
                    </geometry>
                </collision>
            </link>

            <!-- ====================================================================== -->
            <!-- #################### JOINTS SECTION (START) #########################  -->
            <!-- ====================================================================== -->
            <!-- LEFT WHEEL -->
            <!--left back wheel joint-->
            <joint name='left_back_wheel_joint' type='revolute'>
                <pose relative_to='left_back_wheel'/>
                <parent>chassis</parent>
                <child>left_back_wheel</child>
                <axis>
                    <xyz expressed_in='__model__'>0 1 0</xyz>                    <!--can be descired to any frame or even arbitrary frames-->
                    <limit>
                        <lower>-1.79769e+308</lower>                        <!--negative infinity-->
                        <upper>1.79769e+308</upper>                        <!--positive infinity-->
                    </limit>
                </axis>
            </joint>
            <!--left front wheel joint-->
            <joint name='left_front_wheel_joint' type='revolute'>
                <pose relative_to='left_front_wheel'/>
                <parent>chassis</parent>
                <child>left_front_wheel</child>
                <axis>
                    <xyz expressed_in='__model__'>0 1 0</xyz>                    <!--can be descired to any frame or even arbitrary frames-->
                    <limit>
                        <lower>-1.79769e+308</lower>                        <!--negative infinity-->
                        <upper>1.79769e+308</upper>                        <!--positive infinity-->
                    </limit>
                </axis>
            </joint>

            <!-- RIGHT WHEEL -->
            <!--right back wheel joint-->
            <joint name='right_back_wheel_joint' type='revolute'>
                <pose relative_to='right_back_wheel'/>
                <parent>chassis</parent>
                <child>right_back_wheel</child>
                <axis>
                    <xyz expressed_in='__model__'>0 1 0</xyz>
                    <limit>
                        <lower>-1.79769e+308</lower>                        <!--negative infinity-->
                        <upper>1.79769e+308</upper>                        <!--positive infinity-->
                    </limit>
                </axis>
            </joint>
            <!--right front wheel joint-->
            <joint name='right_front_wheel_joint' type='revolute'>
                <pose relative_to='right_front_wheel'/>
                <parent>chassis</parent>
                <child>right_front_wheel</child>
                <axis>
                    <xyz expressed_in='__model__'>0 1 0</xyz>
                    <limit>
                        <lower>-1.79769e+308</lower>                        <!--negative infinity-->
                        <upper>1.79769e+308</upper>                        <!--positive infinity-->
                    </limit>
                </axis>
            </joint>


            <!--caster wheel joint-->            <!--pose defult value is the child-->
            <joint name='caster_wheel' type='ball'>
                <parent>chassis</parent>
                <child>caster</child>
            </joint>
            <!-- ====================================================================== -->
            <!-- ####################### JOINTS SECTION (END) #########################  -->
            <!-- ====================================================================== -->
        </model>
    </world>
</sdf>